Traceback (most recent call last):
  File "/home/frmuno/anaconda3/envs/jupyterbook/lib/python3.8/site-packages/jupyter_cache/executors/utils.py", line 51, in single_nb_execution
    executenb(
  File "/home/frmuno/anaconda3/envs/jupyterbook/lib/python3.8/site-packages/nbclient/client.py", line 1112, in execute
    return NotebookClient(nb=nb, resources=resources, km=km, **kwargs).execute()
  File "/home/frmuno/anaconda3/envs/jupyterbook/lib/python3.8/site-packages/nbclient/util.py", line 74, in wrapped
    return just_run(coro(*args, **kwargs))
  File "/home/frmuno/anaconda3/envs/jupyterbook/lib/python3.8/site-packages/nbclient/util.py", line 53, in just_run
    return loop.run_until_complete(coro)
  File "/home/frmuno/anaconda3/envs/jupyterbook/lib/python3.8/asyncio/base_events.py", line 616, in run_until_complete
    return future.result()
  File "/home/frmuno/anaconda3/envs/jupyterbook/lib/python3.8/site-packages/nbclient/client.py", line 553, in async_execute
    await self.async_execute_cell(
  File "/home/frmuno/anaconda3/envs/jupyterbook/lib/python3.8/site-packages/nbclient/client.py", line 857, in async_execute_cell
    self._check_raise_for_error(cell, exec_reply)
  File "/home/frmuno/anaconda3/envs/jupyterbook/lib/python3.8/site-packages/nbclient/client.py", line 760, in _check_raise_for_error
    raise CellExecutionError.from_cell_and_msg(cell, exec_reply_content)
nbclient.exceptions.CellExecutionError: An error occurred while executing the following cell:
------------------
mds = MDS(n_components=3, dissimilarity='precomputed',random_state=1234, n_init=100, max_iter=1000)
results = mds.fit(distmat.values)
parties = distmat.columns
coords = results.embedding_
import plotly.graph_objects as go
# Create figure
fig = go.Figure()

# Loop df columns and plot columns to the figure
for label, x, y, z in zip(parties, coords[:, 0], coords[:, 1], coords[:, 2]):
    fig.add_trace(go.Scatter3d(x=[x], y=[y], z=[z],
                        text=label,
                        textposition="top center",
                        mode='markers+text', # 'lines' or 'markers'
                        name=label))
fig.update_layout(
    width = 1000,
    height = 1000,
    title = "15th Legislature: 3D MDS",
    template="plotly_white",
    showlegend=False
)
fig.update_yaxes(
    scaleanchor = "x",
    scaleratio = 1,
  )
plot(fig, filename = 'l15-3d-mds.html')
display(HTML('l15-3d-mds.html'))
------------------

[0;31m---------------------------------------------------------------------------[0m
[0;31mTypeError[0m                                 Traceback (most recent call last)
[0;32m/tmp/ipykernel_109287/3915135355.py[0m in [0;36m<module>[0;34m[0m
[1;32m     25[0m     [0mscaleratio[0m [0;34m=[0m [0;36m1[0m[0;34m,[0m[0;34m[0m[0;34m[0m[0m
[1;32m     26[0m   )
[0;32m---> 27[0;31m [0mplot[0m[0;34m([0m[0mfig[0m[0;34m,[0m [0mfilename[0m [0;34m=[0m [0;34m'l15-3d-mds.html'[0m[0;34m)[0m[0;34m[0m[0;34m[0m[0m
[0m[1;32m     28[0m [0mdisplay[0m[0;34m([0m[0mHTML[0m[0;34m([0m[0;34m'l15-3d-mds.html'[0m[0;34m)[0m[0;34m)[0m[0;34m[0m[0;34m[0m[0m

[0;31mTypeError[0m: 'PathCollection' object is not callable
TypeError: 'PathCollection' object is not callable

